Traceback (most recent call last):
  File "/Users/kaihuang1122/Documents/ML/Final/MLP GPT/given_err.py", line 49, in <module>
    loss, mae = model.evaluate(X_test, y_test)
                ^^^^^^^^^^^^^^^^^^^^^^^^^^^^^^
  File "/Library/Frameworks/Python.framework/Versions/3.11/lib/python3.11/site-packages/keras/src/utils/traceback_utils.py", line 65, in error_handler
    return fn(*args, **kwargs)
           ^^^^^^^^^^^^^^^^^^^
  File "/Library/Frameworks/Python.framework/Versions/3.11/lib/python3.11/site-packages/keras/src/engine/training.py", line 2296, in evaluate
    logs = test_function_runner.run_step(
           ^^^^^^^^^^^^^^^^^^^^^^^^^^^^^^
  File "/Library/Frameworks/Python.framework/Versions/3.11/lib/python3.11/site-packages/keras/src/engine/training.py", line 4113, in run_step
    self._callbacks.on_test_batch_end(end_step, logs)
  File "/Library/Frameworks/Python.framework/Versions/3.11/lib/python3.11/site-packages/keras/src/callbacks.py", line 497, in on_test_batch_end
    self._call_batch_hook(ModeKeys.TEST, "end", batch, logs=logs)
  File "/Library/Frameworks/Python.framework/Versions/3.11/lib/python3.11/site-packages/keras/src/callbacks.py", line 322, in _call_batch_hook
    self._call_batch_end_hook(mode, batch, logs)
  File "/Library/Frameworks/Python.framework/Versions/3.11/lib/python3.11/site-packages/keras/src/callbacks.py", line 345, in _call_batch_end_hook
    self._call_batch_hook_helper(hook_name, batch, logs)
  File "/Library/Frameworks/Python.framework/Versions/3.11/lib/python3.11/site-packages/keras/src/callbacks.py", line 392, in _call_batch_hook_helper
    hook = getattr(callback, hook_name)
           ^^^^^^^^^^^^^^^^^^^^^^^^^^^^
KeyboardInterrupt
