Traceback (most recent call last):
  File "/Users/kaihuang1122/Documents/ML/Final/MLP GPT/given_err.py", line 5, in <module>
    import numpy as np
  File "/Library/Frameworks/Python.framework/Versions/3.11/lib/python3.11/site-packages/numpy/__init__.py", line 159, in <module>
    from . import ma
  File "/Library/Frameworks/Python.framework/Versions/3.11/lib/python3.11/site-packages/numpy/ma/__init__.py", line 42, in <module>
    from . import core
  File "/Library/Frameworks/Python.framework/Versions/3.11/lib/python3.11/site-packages/numpy/ma/core.py", line 7958, in <module>
    outer.__doc__ = doc_note(np.outer.__doc__,
                    ^^^^^^^^^^^^^^^^^^^^^^^^^^
  File "/Library/Frameworks/Python.framework/Versions/3.11/lib/python3.11/site-packages/numpy/ma/core.py", line 125, in doc_note
    notesplit = re.split(r'\n\s*?Notes\n\s*?-----', inspect.cleandoc(initialdoc))
                                                    ^^^^^^^^^^^^^^^^^^^^^^^^^^^^
  File "/Library/Frameworks/Python.framework/Versions/3.11/lib/python3.11/inspect.py", line 880, in cleandoc
    content = len(line.lstrip())
                  ^^^^^^^^^^^^^
KeyboardInterrupt
