Traceback (most recent call last):
  File "/Users/kaihuang1122/Documents/ML/Final/MLP GPT/given_err.py", line 5, in <module>
    import numpy as np
  File "/Library/Frameworks/Python.framework/Versions/3.11/lib/python3.11/site-packages/numpy/__init__.py", line 130, in <module>
    from numpy.__config__ import show as show_config
  File "/Library/Frameworks/Python.framework/Versions/3.11/lib/python3.11/site-packages/numpy/__config__.py", line 4, in <module>
    from numpy.core._multiarray_umath import (
  File "/Library/Frameworks/Python.framework/Versions/3.11/lib/python3.11/site-packages/numpy/core/__init__.py", line 74, in <module>
    from . import numeric
  File "/Library/Frameworks/Python.framework/Versions/3.11/lib/python3.11/site-packages/numpy/core/numeric.py", line 2528, in <module>
    extend_all(arrayprint)
  File "/Library/Frameworks/Python.framework/Versions/3.11/lib/python3.11/site-packages/numpy/core/numeric.py", line 2508, in extend_all
    existing = set(__all__)
               ^^^^^^^^^^^^
KeyboardInterrupt
