Traceback (most recent call last):
  File "/Library/Frameworks/Python.framework/Versions/3.11/lib/python3.11/site-packages/numpy/compat/py3k.py", line 24, in <module>
    import pickle5 as pickle
ModuleNotFoundError: No module named 'pickle5'

During handling of the above exception, another exception occurred:

Traceback (most recent call last):
  File "/Users/kaihuang1122/Documents/ML/Final/MLP GPT/given_err.py", line 5, in <module>
    import numpy as np
  File "/Library/Frameworks/Python.framework/Versions/3.11/lib/python3.11/site-packages/numpy/__init__.py", line 130, in <module>
    from numpy.__config__ import show as show_config
  File "/Library/Frameworks/Python.framework/Versions/3.11/lib/python3.11/site-packages/numpy/__config__.py", line 4, in <module>
    from numpy.core._multiarray_umath import (
  File "/Library/Frameworks/Python.framework/Versions/3.11/lib/python3.11/site-packages/numpy/core/__init__.py", line 72, in <module>
    from . import numerictypes as nt
  File "/Library/Frameworks/Python.framework/Versions/3.11/lib/python3.11/site-packages/numpy/core/numerictypes.py", line 105, in <module>
    from ._type_aliases import (
  File "/Library/Frameworks/Python.framework/Versions/3.11/lib/python3.11/site-packages/numpy/core/_type_aliases.py", line 20, in <module>
    from numpy.compat import unicode
  File "/Library/Frameworks/Python.framework/Versions/3.11/lib/python3.11/site-packages/numpy/compat/__init__.py", line 14, in <module>
    from . import py3k
  File "/Library/Frameworks/Python.framework/Versions/3.11/lib/python3.11/site-packages/numpy/compat/py3k.py", line 26, in <module>
    import pickle
  File "/Library/Frameworks/Python.framework/Versions/3.11/lib/python3.11/pickle.py", line 43, in <module>
    from _pickle import PickleBuffer
KeyboardInterrupt
