Traceback (most recent call last):
  File "/Users/kaihuang1122/Documents/ML/Final/MLP GPT/given_err.py", line 3, in <module>
    import csv
  File "/Library/Frameworks/Python.framework/Versions/3.11/lib/python3.11/csv.py", line 6, in <module>
    import re
  File "/Library/Frameworks/Python.framework/Versions/3.11/lib/python3.11/re/__init__.py", line 124, in <module>
    import enum
  File "/Library/Frameworks/Python.framework/Versions/3.11/lib/python3.11/enum.py", line 5, in <module>
    from functools import reduce
  File "/Library/Frameworks/Python.framework/Versions/3.11/lib/python3.11/functools.py", line 18, in <module>
    from collections import namedtuple
  File "/Library/Frameworks/Python.framework/Versions/3.11/lib/python3.11/collections/__init__.py", line 42, in <module>
    from _collections import deque
KeyboardInterrupt
