Traceback (most recent call last):
  File "/Users/kaihuang1122/Documents/ML/Final/MLP GPT/given_err.py", line 5, in <module>
    import numpy as np
  File "/Library/Frameworks/Python.framework/Versions/3.11/lib/python3.11/site-packages/numpy/__init__.py", line 130, in <module>
    from numpy.__config__ import show as show_config
  File "/Library/Frameworks/Python.framework/Versions/3.11/lib/python3.11/site-packages/numpy/__config__.py", line 4, in <module>
    from numpy.core._multiarray_umath import (
  File "/Library/Frameworks/Python.framework/Versions/3.11/lib/python3.11/site-packages/numpy/core/__init__.py", line 104, in <module>
    from . import _internal
  File "/Library/Frameworks/Python.framework/Versions/3.11/lib/python3.11/site-packages/numpy/core/_internal.py", line 7, in <module>
    import ast
  File "/Library/Frameworks/Python.framework/Versions/3.11/lib/python3.11/ast.py", line 28, in <module>
    from _ast import *
KeyboardInterrupt
