Traceback (most recent call last):
  File "/Users/kaihuang1122/Documents/ML/Final/MLP GPT/given_err.py", line 6, in <module>
    from sklearn.model_selection import train_test_split
  File "/Library/Frameworks/Python.framework/Versions/3.11/lib/python3.11/site-packages/sklearn/__init__.py", line 83, in <module>
    from .base import clone
  File "/Library/Frameworks/Python.framework/Versions/3.11/lib/python3.11/site-packages/sklearn/base.py", line 19, in <module>
    from .utils import _IS_32BIT
  File "/Library/Frameworks/Python.framework/Versions/3.11/lib/python3.11/site-packages/sklearn/utils/__init__.py", line 15, in <module>
    from scipy.sparse import issparse
  File "/Library/Frameworks/Python.framework/Versions/3.11/lib/python3.11/site-packages/scipy/__init__.py", line 143, in <module>
    from scipy._lib._ccallback import LowLevelCallable
  File "/Library/Frameworks/Python.framework/Versions/3.11/lib/python3.11/site-packages/scipy/_lib/_ccallback.py", line 1, in <module>
    from . import _ccallback_c
  File "<frozen importlib._bootstrap>", line 405, in parent
KeyboardInterrupt
