Traceback (most recent call last):
  File "/Users/kaihuang1122/Documents/ML/Final/MLP GPT/given_err.py", line 5, in <module>
    import numpy as np
  File "/Library/Frameworks/Python.framework/Versions/3.11/lib/python3.11/site-packages/numpy/__init__.py", line 159, in <module>
    from . import ma
  File "/Library/Frameworks/Python.framework/Versions/3.11/lib/python3.11/site-packages/numpy/ma/__init__.py", line 42, in <module>
    from . import core
  File "/Library/Frameworks/Python.framework/Versions/3.11/lib/python3.11/site-packages/numpy/ma/core.py", line 24, in <module>
    import inspect
  File "/Library/Frameworks/Python.framework/Versions/3.11/lib/python3.11/inspect.py", line 138, in <module>
    import dis
  File "/Library/Frameworks/Python.framework/Versions/3.11/lib/python3.11/dis.py", line 49, in <module>
    _all_opmap[specialized] = spec_op
    ~~~~~~~~~~^^^^^^^^^^^^^
KeyboardInterrupt
