Traceback (most recent call last):
  File "/Users/kaihuang1122/Documents/ML/Final/MLP GPT/given_err.py", line 5, in <module>
    import numpy as np
  File "/Library/Frameworks/Python.framework/Versions/3.11/lib/python3.11/site-packages/numpy/__init__.py", line 156, in <module>
    from . import polynomial
  File "/Library/Frameworks/Python.framework/Versions/3.11/lib/python3.11/site-packages/numpy/polynomial/__init__.py", line 120, in <module>
    from .hermite_e import HermiteE
  File "/Library/Frameworks/Python.framework/Versions/3.11/lib/python3.11/site-packages/numpy/polynomial/hermite_e.py", line 83, in <module>
    from ._polybase import ABCPolyBase
  File "<frozen importlib._bootstrap>", line 405, in parent
KeyboardInterrupt
