Traceback (most recent call last):
  File "/Users/kaihuang1122/Documents/ML/Final/MLP GPT/given_err.py", line 5, in <module>
    import numpy as np
  File "/Library/Frameworks/Python.framework/Versions/3.11/lib/python3.11/site-packages/numpy/__init__.py", line 157, in <module>
    from . import random
  File "/Library/Frameworks/Python.framework/Versions/3.11/lib/python3.11/site-packages/numpy/random/__init__.py", line 180, in <module>
    from . import _pickle
  File "/Library/Frameworks/Python.framework/Versions/3.11/lib/python3.11/site-packages/numpy/random/_pickle.py", line 2, in <module>
    from ._philox import Philox
  File "_philox.pyx", line 1, in init numpy.random._philox
  File "<frozen importlib._bootstrap>", line 216, in _lock_unlock_module
KeyboardInterrupt
